Workbook

Sheet TOE
A1: Name | B1: Type | C1: Class | D1: Tech | E1: Weight | F1: Value
A2: Lightning LTN-G15 | B2: Aerospace Fighter | C2: Medium | D2: IS TW non-box set | E2: 50 | F2: 1845438
A3: Stingray F-90 | B3: Aerospace Fighter | C3: Medium | D3: IS TW non-box set | E3: 60 | F3: 2340182
A4: Boomerang Spotter Plane | B4: Conventional Fighter | C4: Small Support Vehicle | D4: IS TW non-box set | E4: 4.999 | F4: 59439
A5: Leopard (Black Swan Mk III) - The Black Swan | B5: Dropship | C5: Small Dropship | D5: IS TW non-box set | E5: 1900 | F5: 148102200
A6: Union (2708) | B6: Dropship | C6: Medium Dropship | D6: IS TW non-box set | E6: 3600 | F6: 166299000
A7: Gazelle (Heavy Vehicle) Mk II | B7: Dropship | C7: Medium Dropship | D7: IS TW non-box set | E7: 2900 | F7: 146882844
A8: Jump Platoon (Rifle) | B8: Infantry | C8: Light | D8: IS TW non-box set | E8: 4 | F8: 3917659
A9: Jump Platoon (SRM) | B9: Infantry | C9: Light | D9: IS TW non-box set | E9: 3.5 | F9: 3471874
A10: Jump Platoon (Flamer) | B10: Infantry | C10: Light | D10: IS TW non-box set | E10: 4 | F10: 3918439
A11: Jump Platoon (Rifle) #2 | B11: Infantry | C11: Light | D11: IS TW non-box set | E11: 4 | F11: 3917659
A12: Foot Platoon (Laser Marine) | B12: Infantry | C12: Light | D12: IS advanced | E12: 2.5 | F12: 370440
A13: Foot Platoon (Laser Marine) #2 | B13: Infantry | C13: Light | D13: IS advanced | E13: 2.5 | F13: 370440
... A55: Warrior Attack Helicopter H-7 | B55: VTOL | C55: Light | D55: IS TW non-box set | E55: 21 | F55: 168245

Sheet Inventory Summary
A1: Tonnage | B1: Mech Head | C1: In Use | D1: Mech Right Torso | E1: In Use | F1: Mech Left Torso | G1: In Use | H1: Mech Right Arm | I1: In Use | J1: Mech Left Arm | K1: In Use | L1: Mech Gyro | M1: In Use | N1: Mech Sensors | O1: In Use | P1: Mech Life Support System | Q1: In Use | R1: Upper Arm Actuator | S1: In Use | T1: Lower Arm Actuator | U1: In Use | V1: Hand Actuator | W1: In Use | X1: Upper Leg Actator | Y1: In Use | Z1: Lower Leg Actutor | AA1: In Use | AB1: Foot Actuator | AC1: In Use
A2: 20 tons | B2: =COUNTIF('MekHQ Inventory Export'!$1:$1499,"Mech Head "&$A2) -> 1 | C2: =COUNTIF('Parts Required'!$1:$1500,'Inventory Summary'!B$1&" "&'Inventory Summary'!$A2) -> 0 | D2: =COUNTIF('MekHQ Inventory Export'!$1:$1499,"Mech Right Torso "&$A2) -> 1 | E2: =COUNTIF('Parts Required'!$1:$1500,'Inventory Summary'!D$1&" "&'Inventory Summary'!$A2) -> 0 | F2: =COUNTIF('MekHQ Inventory Export'!$1:$1499,"Mech Left Torso"&$A2) -> 0 | G2: =COUNTIF('Parts Required'!$1:$1500,'Inventory Summary'!F$1&" "&'Inventory Summary'!$A2) -> 0 | H2: =COUNTIF('MekHQ Inventory Export'!$1:$1499,"Mech Right Arm "&$A2) -> 0 | I2: =COUNTIF('Parts Required'!$1:$1500,'Inventory Summary'!H$1&" "&'Inventory Summary'!$A2) -> 0 | J2: =COUNTIF('MekHQ Inventory Export'!$1:$1499,"Mech Left Arm "&$A2) -> 0 | K2: =COUNTIF('Parts Required'!$1:$1500,'Inventory Summary'!J$1&" "&'Inventory Summary'!$A2) -> 0 | L2: =COUNTIF('MekHQ Inventory Export'!$1:$1499,"Gyro "&$A2) -> 0 | M2: =COUNTIF('Parts Required'!$1:$1500,'Inventory Summary'!L$1&" "&'Inventory Summary'!$A2) -> 0 | N2: =COUNTIF('MekHQ Inventory Export'!$1:$1499,"Mech Sensors "&$A2) -> 1 | O2: =COUNTIF('Parts Required'!$1:$1500,'Inventory Summary'!N$1&" "&'Inventory Summary'!$A2) -> 0 | P2: =COUNTIF('MekHQ Inventory Export'!$1:$1499,"Mech Life Support System "&$A2) -> 1 | Q2: =COUNTIF('Parts Required'!$1:$1500,'Inventory Summary'!P$1&" "&'Inventory Summary'!$A2) -> 0 | R2: =COUNTIF('MekHQ Inventory Export'!$1:$1499,"Upper Arm Actuator "&$A2) -> 1 | S2: =COUNTIF('Parts Required'!$1:$1500,'Inventory Summary'!R$1&" "&'Inventory Summary'!$A2) -> 0 | T2: =COUNTIF('MekHQ Inventory Export'!$1:$1499,"Lower Arm Actuator "&$A2) -> 0 | U2: =COUNTIF('Parts Required'!$1:$1500,'Inventory Summary'!T$1&" "&'Inventory Summary'!$A2) -> 0 | V2: =COUNTIF('MekHQ Inventory Export'!$1:$1499,"Hamd Actuator "&$A2) -> 0 | W2: =COUNTIF('Parts Required'!$1:$1500,'Inventory Summary'!V$1&" "&'Inventory Summary'!$A2) -> 0 | X2: =COUNTIF('MekHQ Inventory Export'!$1:$1499,"Upper Leg Actuator "&$A2) -> 1 | Y2: =COUNTIF('Parts Required'!$1:$1500,'Inventory Summary'!X$1&" "&'Inventory Summary'!$A2) -> 0 | Z2: =COUNTIF('MekHQ Inventory Export'!$1:$1499,"Lower Leg Actuator"&$A2) -> 0 | AA2: =COUNTIF('Parts Required'!$1:$1500,'Inventory Summary'!Z$1&" "&'Inventory Summary'!$A2) -> 0 | AB2: =COUNTIF('MekHQ Inventory Export'!$1:$1499,"Foot Actuator "&$A2) -> 1 | AC2: =COUNTIF('Parts Required'!$1:$1500,'Inventory Summary'!AB$1&" "&'Inventory Summary'!$A2) -> 0
A3: 25 tons | B3: =COUNTIF('MekHQ Inventory Export'!$1:$1499,"Mech Head "&$A3) -> 0 | C3: =COUNTIF('Parts Required'!$1:$1500,'Inventory Summary'!B$1&" "&'Inventory Summary'!$A3) -> 0 | D3: =COUNTIF('MekHQ Inventory Export'!$1:$1499,"Mech Right Torso "&$A3) -> 0 | E3: =COUNTIF('Parts Required'!$1:$1500,'Inventory Summary'!D$1&" "&'Inventory Summary'!$A3) -> 0 | F3: =COUNTIF('MekHQ Inventory Export'!$1:$1499,"Mech Left Torso"&$A3) -> 0 | G3: =COUNTIF('Parts Required'!$1:$1500,'Inventory Summary'!F$1&" "&'Inventory Summary'!$A3) -> 0 | H3: =COUNTIF('MekHQ Inventory Export'!$1:$1499,"Mech Right Arm "&$A3) -> 0 | I3: =COUNTIF('Parts Required'!$1:$1500,'Inventory Summary'!H$1&" "&'Inventory Summary'!$A3) -> 0 | J3: =COUNTIF('MekHQ Inventory Export'!$1:$1499,"Mech Left Arm "&$A3) -> 0 | K3: =COUNTIF('Parts Required'!$1:$1500,'Inventory Summary'!J$1&" "&'Inventory Summary'!$A3) -> 0 | L3: =COUNTIF('MekHQ Inventory Export'!$1:$1499,"Gyro "&$A3) -> 0 | M3: =COUNTIF('Parts Required'!$1:$1500,'Inventory Summary'!L$1&" "&'Inventory Summary'!$A3) -> 0 | N3: =COUNTIF('MekHQ Inventory Export'!$1:$1499,"Mech Sensors "&$A3) -> 0 | O3: =COUNTIF('Parts Required'!$1:$1500,'Inventory Summary'!N$1&" "&'Inventory Summary'!$A3) -> 0 | P3: =COUNTIF('MekHQ Inventory Export'!$1:$1499,"Mech Life Support System "&$A3) -> 0 | Q3: =COUNTIF('Parts Required'!$1:$1500,'Inventory Summary'!P$1&" "&'Inventory Summary'!$A3) -> 0 | R3: =COUNTIF('MekHQ Inventory Export'!$1:$1499,"Upper Arm Actuator "&$A3) -> 0 | S3: =COUNTIF('Parts Required'!$1:$1500,'Inventory Summary'!R$1&" "&'Inventory Summary'!$A3) -> 0 | T3: =COUNTIF('MekHQ Inventory Export'!$1:$1499,"Lower Arm Actuator "&$A3) -> 0 | U3: =COUNTIF('Parts Required'!$1:$1500,'Inventory Summary'!T$1&" "&'Inventory Summary'!$A3) -> 0 | V3: =COUNTIF('MekHQ Inventory Export'!$1:$1499,"Hamd Actuator "&$A3) -> 0 | W3: =COUNTIF('Parts Required'!$1:$1500,'Inventory Summary'!V$1&" "&'Inventory Summary'!$A3) -> 0 | X3: =COUNTIF('MekHQ Inventory Export'!$1:$1499,"Upper Leg Actuator "&$A3) -> 0 | Y3: =COUNTIF('Parts Required'!$1:$1500,'Inventory Summary'!X$1&" "&'Inventory Summary'!$A3) -> 0 | Z3: =COUNTIF('MekHQ Inventory Export'!$1:$1499,"Lower Leg Actuator"&$A3) -> 0 | AA3: =COUNTIF('Parts Required'!$1:$1500,'Inventory Summary'!Z$1&" "&'Inventory Summary'!$A3) -> 0 | AB3: =COUNTIF('MekHQ Inventory Export'!$1:$1499,"Foot Actuator "&$A3) -> 0 | AC3: =COUNTIF('Parts Required'!$1:$1500,'Inventory Summary'!AB$1&" "&'Inventory Summary'!$A3) -> 0
A4: 30 tons | B4: =COUNTIF('MekHQ Inventory Export'!$1:$1499,"Mech Head "&$A4) -> 1 | C4: =COUNTIF('Parts Required'!$1:$1500,'Inventory Summary'!B$1&" "&'Inventory Summary'!$A4) -> 4 | D4: =COUNTIF('MekHQ Inventory Export'!$1:$1499,"Mech Right Torso "&$A4) -> 1 | E4: =COUNTIF('Parts Required'!$1:$1500,'Inventory Summary'!D$1&" "&'Inventory Summary'!$A4) -> 4 | F4: =COUNTIF('MekHQ Inventory Export'!$1:$1499,"Mech Left Torso"&$A4) -> 0 | G4: =COUNTIF('Parts Required'!$1:$1500,'Inventory Summary'!F$1&" "&'Inventory Summary'!$A4) -> 4 | H4: =COUNTIF('MekHQ Inventory Export'!$1:$1499,"Mech Right Arm "&$A4) -> 1 | I4: =COUNTIF('Parts Required'!$1:$1500,'Inventory Summary'!H$1&" "&'Inventory Summary'!$A4) -> 4 | J4: =COUNTIF('MekHQ Inventory Export'!$1:$1499,"Mech Left Arm "&$A4) -> 1 | K4: =COUNTIF('Parts Required'!$1:$1500,'Inventory Summary'!J$1&" "&'Inventory Summary'!$A4) -> 4 | L4: =COUNTIF('MekHQ Inventory Export'!$1:$1499,"Gyro "&$A4) -> 0 | M4: =COUNTIF('Parts Required'!$1:$1500,'Inventory Summary'!L$1&" "&'Inventory Summary'!$A4) -> 4 | N4: =COUNTIF('MekHQ Inventory Export'!$1:$1499,"Mech Sensors "&$A4) -> 1 | O4: =COUNTIF('Parts Required'!$1:$1500,'Inventory Summary'!N$1&" "&'Inventory Summary'!$A4) -> 0 | P4: =COUNTIF('MekHQ Inventory Export'!$1:$1499,"Mech Life Support System "&$A4) -> 0 | Q4: =COUNTIF('Parts Required'!$1:$1500,'Inventory Summary'!P$1&" "&'Inventory Summary'!$A4) -> 4 | R4: =COUNTIF('MekHQ Inventory Export'!$1:$1499,"Upper Arm Actuator "&$A4) -> 2 | S4: =COUNTIF('Parts Required'!$1:$1500,'Inventory Summary'!R$1&" "&'Inventory Summary'!$A4) -> 4 | T4: =COUNTIF('MekHQ Inventory Export'!$1:$1499,"Lower Arm Actuator "&$A4) -> 2 | U4: =COUNTIF('Parts Required'!$1:$1500,'Inventory Summary'!T$1&" "&'Inventory Summary'!$A4) -> 4 | V4: =COUNTIF('MekHQ Inventory Export'!$1:$1499,"Hamd Actuator "&$A4) -> 0 | W4: =COUNTIF('Parts Required'!$1:$1500,'Inventory Summary'!V$1&" "&'Inventory Summary'!$A4) -> 4 | X4: =COUNTIF('MekHQ Inventory Export'!$1:$1499,"Upper Leg Actuator "&$A4) -> 2 | Y4: =COUNTIF('Parts Required'!$1:$1500,'Inventory Summary'!X$1&" "&'Inventory Summary'!$A4) -> 4 | Z4: =COUNTIF('MekHQ Inventory Export'!$1:$1499,"Lower Leg Actuator"&$A4) -> 0 | AA4: =COUNTIF('Parts Required'!$1:$1500,'Inventory Summary'!Z$1&" "&'Inventory Summary'!$A4) -> 4 | AB4: =COUNTIF('MekHQ Inventory Export'!$1:$1499,"Foot Actuator "&$A4) -> 2 | AC4: =COUNTIF('Parts Required'!$1:$1500,'Inventory Summary'!AB$1&" "&'Inventory Summary'!$A4) -> 4
A5: 35 tons | B5: =COUNTIF('MekHQ Inventory Export'!$1:$1499,"Mech Head "&$A5) -> 1 | C5: =COUNTIF('Parts Required'!$1:$1500,'Inventory Summary'!B$1&" "&'Inventory Summary'!$A5) -> 0 | D5: =COUNTIF('MekHQ Inventory Export'!$1:$1499,"Mech Right Torso "&$A5) -> 1 | E5: =COUNTIF('Parts Required'!$1:$1500,'Inventory Summary'!D$1&" "&'Inventory Summary'!$A5) -> 0 | F5: =COUNTIF('MekHQ Inventory Export'!$1:$1499,"Mech Left Torso"&$A5) -> 0 | G5: =COUNTIF('Parts Required'!$1:$1500,'Inventory Summary'!F$1&" "&'Inventory Summary'!$A5) -> 0 | H5: =COUNTIF('MekHQ Inventory Export'!$1:$1499,"Mech Right Arm "&$A5) -> 1 | I5: =COUNTIF('Parts Required'!$1:$1500,'Inventory Summary'!H$1&" "&'Inventory Summary'!$A5) -> 0 | J5: =COUNTIF('MekHQ Inventory Export'!$1:$1499,"Mech Left Arm "&$A5) -> 1 | K5: =COUNTIF('Parts Required'!$1:$1500,'Inventory Summary'!J$1&" "&'Inventory Summary'!$A5) -> 0 | L5: =COUNTIF('MekHQ Inventory Export'!$1:$1499,"Gyro "&$A5) -> 0 | M5: =COUNTIF('Parts Required'!$1:$1500,'Inventory Summary'!L$1&" "&'Inventory Summary'!$A5) -> 0 | N5: =COUNTIF('MekHQ Inventory Export'!$1:$1499,"Mech Sensors "&$A5) -> 1 | O5: =COUNTIF('Parts Required'!$1:$1500,'Inventory Summary'!N$1&" "&'Inventory Summary'!$A5) -> 0 | P5: =COUNTIF('MekHQ Inventory Export'!$1:$1499,"Mech Life Support System "&$A5) -> 0 | Q5: =COUNTIF('Parts Required'!$1:$1500,'Inventory Summary'!P$1&" "&'Inventory Summary'!$A5) -> 0 | R5: =COUNTIF('MekHQ Inventory Export'!$1:$1499,"Upper Arm Actuator "&$A5) -> 1 | S5: =COUNTIF('Parts Required'!$1:$1500,'Inventory Summary'!R$1&" "&'Inventory Summary'!$A5) -> 0 | T5: =COUNTIF('MekHQ Inventory Export'!$1:$1499,"Lower Arm Actuator "&$A5) -> 1 | U5: =COUNTIF('Parts Required'!$1:$1500,'Inventory Summary'!T$1&" "&'Inventory Summary'!$A5) -> 0 | V5: =COUNTIF('MekHQ Inventory Export'!$1:$1499,"Hamd Actuator "&$A5) -> 0 | W5: =COUNTIF('Parts Required'!$1:$1500,'Inventory Summary'!V$1&" "&'Inventory Summary'!$A5) -> 0 | X5: =COUNTIF('MekHQ Inventory Export'!$1:$1499,"Upper Leg Actuator "&$A5) -> 1 | Y5: =COUNTIF('Parts Required'!$1:$1500,'Inventory Summary'!X$1&" "&'Inventory Summary'!$A5) -> 0 | Z5: =COUNTIF('MekHQ Inventory Export'!$1:$1499,"Lower Leg Actuator"&$A5) -> 0 | AA5: =COUNTIF('Parts Required'!$1:$1500,'Inventory Summary'!Z$1&" "&'Inventory Summary'!$A5) -> 0 | AB5: =COUNTIF('MekHQ Inventory Export'!$1:$1499,"Foot Actuator "&$A5) -> 1 | AC5: =COUNTIF('Parts Required'!$1:$1500,'Inventory Summary'!AB$1&" "&'Inventory Summary'!$A5) -> 0
A6: 40 tons | B6: =COUNTIF('MekHQ Inventory Export'!$1:$1499,"Mech Head "&$A6) -> 0 | C6: =COUNTIF('Parts Required'!$1:$1500,'Inventory Summary'!B$1&" "&'Inventory Summary'!$A6) -> 1 | D6: =COUNTIF('MekHQ Inventory Export'!$1:$1499,"Mech Right Torso "&$A6) -> 1 | E6: =COUNTIF('Parts Required'!$1:$1500,'Inventory Summary'!D$1&" "&'Inventory Summary'!$A6) -> 1 | F6: =COUNTIF('MekHQ Inventory Export'!$1:$1499,"Mech Left Torso"&$A6) -> 0 | G6: =COUNTIF('Parts Required'!$1:$1500,'Inventory Summary'!F$1&" "&'Inventory Summary'!$A6) -> 1 | H6: =COUNTIF('MekHQ Inventory Export'!$1:$1499,"Mech Right Arm "&$A6) -> 1 | I6: =COUNTIF('Parts Required'!$1:$1500,'Inventory Summary'!H$1&" "&'Inventory Summary'!$A6) -> 1 | J6: =COUNTIF('MekHQ Inventory Export'!$1:$1499,"Mech Left Arm "&$A6) -> 1 | K6: =COUNTIF('Parts Required'!$1:$1500,'Inventory Summary'!J$1&" "&'Inventory Summary'!$A6) -> 1 | L6: =COUNTIF('MekHQ Inventory Export'!$1:$1499,"Gyro "&$A6) -> 0 | M6: =COUNTIF('Parts Required'!$1:$1500,'Inventory Summary'!L$1&" "&'Inventory Summary'!$A6) -> 1 | N6: =COUNTIF('MekHQ Inventory Export'!$1:$1499,"Mech Sensors "&$A6) -> 1 | O6: =COUNTIF('Parts Required'!$1:$1500,'Inventory Summary'!N$1&" "&'Inventory Summary'!$A6) -> 0 | P6: =COUNTIF('MekHQ Inventory Export'!$1:$1499,"Mech Life Support System "&$A6) -> 0 | Q6: =COUNTIF('Parts Required'!$1:$1500,'Inventory Summary'!P$1&" "&'Inventory Summary'!$A6) -> 1 | R6: =COUNTIF('MekHQ Inventory Export'!$1:$1499,"Upper Arm Actuator "&$A6) -> 1 | S6: =COUNTIF('Parts Required'!$1:$1500,'Inventory Summary'!R$1&" "&'Inventory Summary'!$A6) -> 1 | T6: =COUNTIF('MekHQ Inventory Export'!$1:$1499,"Lower Arm Actuator "&$A6) -> 1 | U6: =COUNTIF('Parts Required'!$1:$1500,'Inventory Summary'!T$1&" "&'Inventory Summary'!$A6) -> 1 | V6: =COUNTIF('MekHQ Inventory Export'!$1:$1499,"Hamd Actuator "&$A6) -> 0 | W6: =COUNTIF('Parts Required'!$1:$1500,'Inventory Summary'!V$1&" "&'Inventory Summary'!$A6) -> 1 | X6: =COUNTIF('MekHQ Inventory Export'!$1:$1499,"Upper Leg Actuator "&$A6) -> 1 | Y6: =COUNTIF('Parts Required'!$1:$1500,'Inventory Summary'!X$1&" "&'Inventory Summary'!$A6) -> 1 | Z6: =COUNTIF('MekHQ Inventory Export'!$1:$1499,"Lower Leg Actuator"&$A6) -> 0 | AA6: =COUNTIF('Parts Required'!$1:$1500,'Inventory Summary'!Z$1&" "&'Inventory Summary'!$A6) -> 1 | AB6: =COUNTIF('MekHQ Inventory Export'!$1:$1499,"Foot Actuator "&$A6) -> 1 | AC6: =COUNTIF('Parts Required'!$1:$1500,'Inventory Summary'!AB$1&" "&'Inventory Summary'!$A6) -> 1
A7: 45 tons | B7: =COUNTIF('MekHQ Inventory Export'!$1:$1499,"Mech Head "&$A7) -> 0 | C7: =COUNTIF('Parts Required'!$1:$1500,'Inventory Summary'!B$1&" "&'Inventory Summary'!$A7) -> 0 | D7: =COUNTIF('MekHQ Inventory Export'!$1:$1499,"Mech Right Torso "&$A7) -> 0 | E7: =COUNTIF('Parts Required'!$1:$1500,'Inventory Summary'!D$1&" "&'Inventory Summary'!$A7) -> 0 | F7: =COUNTIF('MekHQ Inventory Export'!$1:$1499,"Mech Left Torso"&$A7) -> 0 | G7: =COUNTIF('Parts Required'!$1:$1500,'Inventory Summary'!F$1&" "&'Inventory Summary'!$A7) -> 0 | H7: =COUNTIF('MekHQ Inventory Export'!$1:$1499,"Mech Right Arm "&$A7) -> 0 | I7: =COUNTIF('Parts Required'!$1:$1500,'Inventory Summary'!H$1&" "&'Inventory Summary'!$A7) -> 0 | J7: =COUNTIF('MekHQ Inventory Export'!$1:$1499,"Mech Left Arm "&$A7) -> 0 | K7: =COUNTIF('Parts Required'!$1:$1500,'Inventory Summary'!J$1&" "&'Inventory Summary'!$A7) -> 0 | L7: =COUNTIF('MekHQ Inventory Export'!$1:$1499,"Gyro "&$A7) -> 0 | M7: =COUNTIF('Parts Required'!$1:$1500,'Inventory Summary'!L$1&" "&'Inventory Summary'!$A7) -> 0 | N7: =COUNTIF('MekHQ Inventory Export'!$1:$1499,"Mech Sensors "&$A7) -> 0 | O7: =COUNTIF('Parts Required'!$1:$1500,'Inventory Summary'!N$1&" "&'Inventory Summary'!$A7) -> 0 | P7: =COUNTIF('MekHQ Inventory Export'!$1:$1499,"Mech Life Support System "&$A7) -> 0 | Q7: =COUNTIF('Parts Required'!$1:$1500,'Inventory Summary'!P$1&" "&'Inventory Summary'!$A7) -> 0 | R7: =COUNTIF('MekHQ Inventory Export'!$1:$1499,"Upper Arm Actuator "&$A7) -> 1 | S7: =COUNTIF('Parts Required'!$1:$1500,'Inventory Summary'!R$1&" "&'Inventory Summary'!$A7) -> 0 | T7: =COUNTIF('MekHQ Inventory Export'!$1:$1499,"Lower Arm Actuator "&$A7) -> 1 | U7: =COUNTIF('Parts Required'!$1:$1500,'Inventory Summary'!T$1&" "&'Inventory Summary'!$A7) -> 0 | V7: =COUNTIF('MekHQ Inventory Export'!$1:$1499,"Hamd Actuator "&$A7) -> 0 | W7: =COUNTIF('Parts Required'!$1:$1500,'Inventory Summary'!V$1&" "&'Inventory Summary'!$A7) -> 0 | X7: =COUNTIF('MekHQ Inventory Export'!$1:$1499,"Upper Leg Actuator "&$A7) -> 0 | Y7: =COUNTIF('Parts Required'!$1:$1500,'Inventory Summary'!X$1&" "&'Inventory Summary'!$A7) -> 0 | Z7: =COUNTIF('MekHQ Inventory Export'!$1:$1499,"Lower Leg Actuator"&$A7) -> 0 | AA7: =COUNTIF('Parts Required'!$1:$1500,'Inventory Summary'!Z$1&" "&'Inventory Summary'!$A7) -> 0 | AB7: =COUNTIF('MekHQ Inventory Export'!$1:$1499,"Foot Actuator "&$A7) -> 0 | AC7: =COUNTIF('Parts Required'!$1:$1500,'Inventory Summary'!AB$1&" "&'Inventory Summary'!$A7) -> 0
A8: 50 tons | B8: =COUNTIF('MekHQ Inventory Export'!$1:$1499,"Mech Head "&$A8) -> 1 | C8: =COUNTIF('Parts Required'!$1:$1500,'Inventory Summary'!B$1&" "&'Inventory Summary'!$A8) -> 4 | D8: =COUNTIF('MekHQ Inventory Export'!$1:$1499,"Mech Right Torso "&$A8) -> 1 | E8: =COUNTIF('Parts Required'!$1:$1500,'Inventory Summary'!D$1&" "&'Inventory Summary'!$A8) -> 4 | F8: =COUNTIF('MekHQ Inventory Export'!$1:$1499,"Mech Left Torso"&$A8) -> 0 | G8: =COUNTIF('Parts Required'!$1:$1500,'Inventory Summary'!F$1&" "&'Inventory Summary'!$A8) -> 4 | H8: =COUNTIF('MekHQ Inventory Export'!$1:$1499,"Mech Right Arm "&$A8) -> 0 | I8: =COUNTIF('Parts Required'!$1:$1500,'Inventory Summary'!H$1&" "&'Inventory Summary'!$A8) -> 4 | J8: =COUNTIF('MekHQ Inventory Export'!$1:$1499,"Mech Left Arm "&$A8) -> 0 | K8: =COUNTIF('Parts Required'!$1:$1500,'Inventory Summary'!J$1&" "&'Inventory Summary'!$A8) -> 4 | L8: =COUNTIF('MekHQ Inventory Export'!$1:$1499,"Gyro "&$A8) -> 0 | M8: =COUNTIF('Parts Required'!$1:$1500,'Inventory Summary'!L$1&" "&'Inventory Summary'!$A8) -> 4 | N8: =COUNTIF('MekHQ Inventory Export'!$1:$1499,"Mech Sensors "&$A8) -> 1 | O8: =COUNTIF('Parts Required'!$1:$1500,'Inventory Summary'!N$1&" "&'Inventory Summary'!$A8) -> 0 | P8: =COUNTIF('MekHQ Inventory Export'!$1:$1499,"Mech Life Support System "&$A8) -> 1 | Q8: =COUNTIF('Parts Required'!$1:$1500,'Inventory Summary'!P$1&" "&'Inventory Summary'!$A8) -> 4 | R8: =COUNTIF('MekHQ Inventory Export'!$1:$1499,"Upper Arm Actuator "&$A8) -> 2 | S8: =COUNTIF('Parts Required'!$1:$1500,'Inventory Summary'!R$1&" "&'Inventory Summary'!$A8) -> 4 | T8: =COUNTIF('MekHQ Inventory Export'!$1:$1499,"Lower Arm Actuator "&$A8) -> 2 | U8: =COUNTIF('Parts Required'!$1:$1500,'Inventory Summary'!T$1&" "&'Inventory Summary'!$A8) -> 4 | V8: =COUNTIF('MekHQ Inventory Export'!$1:$1499,"Hamd Actuator "&$A8) -> 0 | W8: =COUNTIF('Parts Required'!$1:$1500,'Inventory Summary'!V$1&" "&'Inventory Summary'!$A8) -> 4 | X8: =COUNTIF('MekHQ Inventory Export'!$1:$1499,"Upper Leg Actuator "&$A8) -> 1 | Y8: =COUNTIF('Parts Required'!$1:$1500,'Inventory Summary'!X$1&" "&'Inventory Summary'!$A8) -> 4 | Z8: =COUNTIF('MekHQ Inventory Export'!$1:$1499,"Lower Leg Actuator"&$A8) -> 0 | AA8: =COUNTIF('Parts Required'!$1:$1500,'Inventory Summary'!Z$1&" "&'Inventory Summary'!$A8) -> 4 | AB8: =COUNTIF('MekHQ Inventory Export'!$1:$1499,"Foot Actuator "&$A8) -> 1 | AC8: =COUNTIF('Parts Required'!$1:$1500,'Inventory Summary'!AB$1&" "&'Inventory Summary'!$A8) -> 4
A9: 55 tons | B9: =COUNTIF('MekHQ Inventory Export'!$1:$1499,"Mech Head "&$A9) -> 0 | C9: =COUNTIF('Parts Required'!$1:$1500,'Inventory Summary'!B$1&" "&'Inventory Summary'!$A9) -> 2 | D9: =COUNTIF('MekHQ Inventory Export'!$1:$1499,"Mech Right Torso "&$A9) -> 0 | E9: =COUNTIF('Parts Required'!$1:$1500,'Inventory Summary'!D$1&" "&'Inventory Summary'!$A9) -> 2 | F9: =COUNTIF('MekHQ Inventory Export'!$1:$1499,"Mech Left Torso"&$A9) -> 0 | G9: =COUNTIF('Parts Required'!$1:$1500,'Inventory Summary'!F$1&" "&'Inventory Summary'!$A9) -> 2 | H9: =COUNTIF('MekHQ Inventory Export'!$1:$1499,"Mech Right Arm "&$A9) -> 0 | I9: =COUNTIF('Parts Required'!$1:$1500,'Inventory Summary'!H$1&" "&'Inventory Summary'!$A9) -> 2 | J9: =COUNTIF('MekHQ Inventory Export'!$1:$1499,"Mech Left Arm "&$A9) -> 1 | K9: =COUNTIF('Parts Required'!$1:$1500,'Inventory Summary'!J$1&" "&'Inventory Summary'!$A9) -> 2 | L9: =COUNTIF('MekHQ Inventory Export'!$1:$1499,"Gyro "&$A9) -> 0 | M9: =COUNTIF('Parts Required'!$1:$1500,'Inventory Summary'!L$1&" "&'Inventory Summary'!$A9) -> 2 | N9: =COUNTIF('MekHQ Inventory Export'!$1:$1499,"Mech Sensors "&$A9) -> 1 | O9: =COUNTIF('Parts Required'!$1:$1500,'Inventory Summary'!N$1&" "&'Inventory Summary'!$A9) -> 0 | P9: =COUNTIF('MekHQ Inventory Export'!$1:$1499,"Mech Life Support System "&$A9) -> 0 | Q9: =COUNTIF('Parts Required'!$1:$1500,'Inventory Summary'!P$1&" "&'Inventory Summary'!$A9) -> 2 | R9: =COUNTIF('MekHQ Inventory Export'!$1:$1499,"Upper Arm Actuator "&$A9) -> 1 | S9: =COUNTIF('Parts Required'!$1:$1500,'Inventory Summary'!R$1&" "&'Inventory Summary'!$A9) -> 2 | T9: =COUNTIF('MekHQ Inventory Export'!$1:$1499,"Lower Arm Actuator "&$A9) -> 1 | U9: =COUNTIF('Parts Required'!$1:$1500,'Inventory Summary'!T$1&" "&'Inventory Summary'!$A9) -> 2 | V9: =COUNTIF('MekHQ Inventory Export'!$1:$1499,"Hamd Actuator "&$A9) -> 0 | W9: =COUNTIF('Parts Required'!$1:$1500,'Inventory Summary'!V$1&" "&'Inventory Summary'!$A9) -> 2 | X9: =COUNTIF('MekHQ Inventory Export'!$1:$1499,"Upper Leg Actuator "&$A9) -> 1 | Y9: =COUNTIF('Parts Required'!$1:$1500,'Inventory Summary'!X$1&" "&'Inventory Summary'!$A9) -> 2 | Z9: =COUNTIF('MekHQ Inventory Export'!$1:$1499,"Lower Leg Actuator"&$A9) -> 0 | AA9: =COUNTIF('Parts Required'!$1:$1500,'Inventory Summary'!Z$1&" "&'Inventory Summary'!$A9) -> 2 | AB9: =COUNTIF('MekHQ Inventory Export'!$1:$1499,"Foot Actuator "&$A9) -> 1 | AC9: =COUNTIF('Parts Required'!$1:$1500,'Inventory Summary'!AB$1&" "&'Inventory Summary'!$A9) -> 2
A10: 60 tons | B10: =COUNTIF('MekHQ Inventory Export'!$1:$1499,"Mech Head "&$A10) -> 1 | C10: =COUNTIF('Parts Required'!$1:$1500,'Inventory Summary'!B$1&" "&'Inventory Summary'!$A10) -> 1 | D10: =COUNTIF('MekHQ Inventory Export'!$1:$1499,"Mech Right Torso "&$A10) -> 1 | E10: =COUNTIF('Parts Required'!$1:$1500,'Inventory Summary'!D$1&" "&'Inventory Summary'!$A10) -> 1 | F10: =COUNTIF('MekHQ Inventory Export'!$1:$1499,"Mech Left Torso"&$A10) -> 0 | G10: =COUNTIF('Parts Required'!$1:$1500,'Inventory Summary'!F$1&" "&'Inventory Summary'!$A10) -> 1 | H10: =COUNTIF('MekHQ Inventory Export'!$1:$1499,"Mech Right Arm "&$A10) -> 1 | I10: =COUNTIF('Parts Required'!$1:$1500,'Inventory Summary'!H$1&" "&'Inventory Summary'!$A10) -> 1 | J10: =COUNTIF('MekHQ Inventory Export'!$1:$1499,"Mech Left Arm "&$A10) -> 1 | K10: =COUNTIF('Parts Required'!$1:$1500,'Inventory Summary'!J$1&" "&'Inventory Summary'!$A10) -> 1 | L10: =COUNTIF('MekHQ Inventory Export'!$1:$1499,"Gyro "&$A10) -> 0 | M10: =COUNTIF('Parts Required'!$1:$1500,'Inventory Summary'!L$1&" "&'Inventory Summary'!$A10) -> 1 | N10: =COUNTIF('MekHQ Inventory Export'!$1:$1499,"Mech Sensors "&$A10) -> 1 | O10: =COUNTIF('Parts Required'!$1:$1500,'Inventory Summary'!N$1&" "&'Inventory Summary'!$A10) -> 0 | P10: =COUNTIF('MekHQ Inventory Export'!$1:$1499,"Mech Life Support System "&$A10) -> 0 | Q10: =COUNTIF('Parts Required'!$1:$1500,'Inventory Summary'!P$1&" "&'Inventory Summary'!$A10) -> 1 | R10: =COUNTIF('MekHQ Inventory Export'!$1:$1499,"Upper Arm Actuator "&$A10) -> 1 | S10: =COUNTIF('Parts Required'!$1:$1500,'Inventory Summary'!R$1&" "&'Inventory Summary'!$A10) -> 1 | T10: =COUNTIF('MekHQ Inventory Export'!$1:$1499,"Lower Arm Actuator "&$A10) -> 1 | U10: =COUNTIF('Parts Required'!$1:$1500,'Inventory Summary'!T$1&" "&'Inventory Summary'!$A10) -> 1 | V10: =COUNTIF('MekHQ Inventory Export'!$1:$1499,"Hamd Actuator "&$A10) -> 0 | W10: =COUNTIF('Parts Required'!$1:$1500,'Inventory Summary'!V$1&" "&'Inventory Summary'!$A10) -> 1 | X10: =COUNTIF('MekHQ Inventory Export'!$1:$1499,"Upper Leg Actuator "&$A10) -> 1 | Y10: =COUNTIF('Parts Required'!$1:$1500,'Inventory Summary'!X$1&" "&'Inventory Summary'!$A10) -> 1 | Z10: =COUNTIF('MekHQ Inventory Export'!$1:$1499,"Lower Leg Actuator"&$A10) -> 0 | AA10: =COUNTIF('Parts Required'!$1:$1500,'Inventory Summary'!Z$1&" "&'Inventory Summary'!$A10) -> 1 | AB10: =COUNTIF('MekHQ Inventory Export'!$1:$1499,"Foot Actuator "&$A10) -> 2 | AC10: =COUNTIF('Parts Required'!$1:$1500,'Inventory Summary'!AB$1&" "&'Inventory Summary'!$A10) -> 1
A11: 65 tons | B11: =COUNTIF('MekHQ Inventory Export'!$1:$1499,"Mech Head "&$A11) -> 1 | C11: =COUNTIF('Parts Required'!$1:$1500,'Inventory Summary'!B$1&" "&'Inventory Summary'!$A11) -> 2 | D11: =COUNTIF('MekHQ Inventory Export'!$1:$1499,"Mech Right Torso "&$A11) -> 0 | E11: =COUNTIF('Parts Required'!$1:$1500,'Inventory Summary'!D$1&" "&'Inventory Summary'!$A11) -> 2 | F11: =COUNTIF('MekHQ Inventory Export'!$1:$1499,"Mech Left Torso"&$A11) -> 0 | G11: =COUNTIF('Parts Required'!$1:$1500,'Inventory Summary'!F$1&" "&'Inventory Summary'!$A11) -> 2 | H11: =COUNTIF('MekHQ Inventory Export'!$1:$1499,"Mech Right Arm "&$A11) -> 1 | I11: =COUNTIF('Parts Required'!$1:$1500,'Inventory Summary'!H$1&" "&'Inventory Summary'!$A11) -> 2 | J11: =COUNTIF('MekHQ Inventory Export'!$1:$1499,"Mech Left Arm "&$A11) -> 0 | K11: =COUNTIF('Parts Required'!$1:$1500,'Inventory Summary'!J$1&" "&'Inventory Summary'!$A11) -> 2 | L11: =COUNTIF('MekHQ Inventory Export'!$1:$1499,"Gyro "&$A11) -> 0 | M11: =COUNTIF('Parts Required'!$1:$1500,'Inventory Summary'!L$1&" "&'Inventory Summary'!$A11) -> 2 | N11: =COUNTIF('MekHQ Inventory Export'!$1:$1499,"Mech Sensors "&$A11) -> 1 | O11: =COUNTIF('Parts Required'!$1:$1500,'Inventory Summary'!N$1&" "&'Inventory Summary'!$A11) -> 0 | P11: =COUNTIF('MekHQ Inventory Export'!$1:$1499,"Mech Life Support System "&$A11) -> 0 | Q11: =COUNTIF('Parts Required'!$1:$1500,'Inventory Summary'!P$1&" "&'Inventory Summary'!$A11) -> 2 | R11: =COUNTIF('MekHQ Inventory Export'!$1:$1499,"Upper Arm Actuator "&$A11) -> 1 | S11: =COUNTIF('Parts Required'!$1:$1500,'Inventory Summary'!R$1&" "&'Inventory Summary'!$A11) -> 2 | T11: =COUNTIF('MekHQ Inventory Export'!$1:$1499,"Lower Arm Actuator "&$A11) -> 1 | U11: =COUNTIF('Parts Required'!$1:$1500,'Inventory Summary'!T$1&" "&'Inventory Summary'!$A11) -> 2 | V11: =COUNTIF('MekHQ Inventory Export'!$1:$1499,"Hamd Actuator "&$A11) -> 0 | W11: =COUNTIF('Parts Required'!$1:$1500,'Inventory Summary'!V$1&" "&'Inventory Summary'!$A11) -> 2 | X11: =COUNTIF('MekHQ Inventory Export'!$1:$1499,"Upper Leg Actuator "&$A11) -> 1 | Y11: =COUNTIF('Parts Required'!$1:$1500,'Inventory Summary'!X$1&" "&'Inventory Summary'!$A11) -> 2 | Z11: =COUNTIF('MekHQ Inventory Export'!$1:$1499,"Lower Leg Actuator"&$A11) -> 0 | AA11: =COUNTIF('Parts Required'!$1:$1500,'Inventory Summary'!Z$1&" "&'Inventory Summary'!$A11) -> 2 | AB11: =COUNTIF('MekHQ Inventory Export'!$1:$1499,"Foot Actuator "&$A11) -> 1 | AC11: =COUNTIF('Parts Required'!$1:$1500,'Inventory Summary'!AB$1&" "&'Inventory Summary'!$A11) -> 2
A12: 70 tons | B12: =COUNTIF('MekHQ Inventory Export'!$1:$1499,"Mech Head "&$A12) -> 0 | C12: =COUNTIF('Parts Required'!$1:$1500,'Inventory Summary'!B$1&" "&'Inventory Summary'!$A12) -> 1 | D12: =COUNTIF('MekHQ Inventory Export'!$1:$1499,"Mech Right Torso "&$A12) -> 0 | E12: =COUNTIF('Parts Required'!$1:$1500,'Inventory Summary'!D$1&" "&'Inventory Summary'!$A12) -> 1 | F12: =COUNTIF('MekHQ Inventory Export'!$1:$1499,"Mech Left Torso"&$A12) -> 0 | G12: =COUNTIF('Parts Required'!$1:$1500,'Inventory Summary'!F$1&" "&'Inventory Summary'!$A12) -> 1 | H12: =COUNTIF('MekHQ Inventory Export'!$1:$1499,"Mech Right Arm "&$A12) -> 0 | I12: =COUNTIF('Parts Required'!$1:$1500,'Inventory Summary'!H$1&" "&'Inventory Summary'!$A12) -> 1 | J12: =COUNTIF('MekHQ Inventory Export'!$1:$1499,"Mech Left Arm "&$A12) -> 0 | K12: =COUNTIF('Parts Required'!$1:$1500,'Inventory Summary'!J$1&" "&'Inventory Summary'!$A12) -> 1 | L12: =COUNTIF('MekHQ Inventory Export'!$1:$1499,"Gyro "&$A12) -> 0 | M12: =COUNTIF('Parts Required'!$1:$1500,'Inventory Summary'!L$1&" "&'Inventory Summary'!$A12) -> 1 | N12: =COUNTIF('MekHQ Inventory Export'!$1:$1499,"Mech Sensors "&$A12) -> 1 | O12: =COUNTIF('Parts Required'!$1:$1500,'Inventory Summary'!N$1&" "&'Inventory Summary'!$A12) -> 0 | P12: =COUNTIF('MekHQ Inventory Export'!$1:$1499,"Mech Life Support System "&$A12) -> 0 | Q12: =COUNTIF('Parts Required'!$1:$1500,'Inventory Summary'!P$1&" "&'Inventory Summary'!$A12) -> 1 | R12: =COUNTIF('MekHQ Inventory Export'!$1:$1499,"Upper Arm Actuator "&$A12) -> 1 | S12: =COUNTIF('Parts Required'!$1:$1500,'Inventory Summary'!R$1&" "&'Inventory Summary'!$A12) -> 1 | T12: =COUNTIF('MekHQ Inventory Export'!$1:$1499,"Lower Arm Actuator "&$A12) -> 1 | U12: =COUNTIF('Parts Required'!$1:$1500,'Inventory Summary'!T$1&" "&'Inventory Summary'!$A12) -> 1 | V12: =COUNTIF('MekHQ Inventory Export'!$1:$1499,"Hamd Actuator "&$A12) -> 0 | W12: =COUNTIF('Parts Required'!$1:$1500,'Inventory Summary'!V$1&" "&'Inventory Summary'!$A12) -> 1 | X12: =COUNTIF('MekHQ Inventory Export'!$1:$1499,"Upper Leg Actuator "&$A12) -> 2 | Y12: =COUNTIF('Parts Required'!$1:$1500,'Inventory Summary'!X$1&" "&'Inventory Summary'!$A12) -> 1 | Z12: =COUNTIF('MekHQ Inventory Export'!$1:$1499,"Lower Leg Actuator"&$A12) -> 0 | AA12: =COUNTIF('Parts Required'!$1:$1500,'Inventory Summary'!Z$1&" "&'Inventory Summary'!$A12) -> 1 | AB12: =COUNTIF('MekHQ Inventory Export'!$1:$1499,"Foot Actuator "&$A12) -> 1 | AC12: =COUNTIF('Parts Required'!$1:$1500,'Inventory Summary'!AB$1&" "&'Inventory Summary'!$A12) -> 1
A13: 75 tons | B13: =COUNTIF('MekHQ Inventory Export'!$1:$1499,"Mech Head "&$A13) -> 0 | C13: =COUNTIF('Parts Required'!$1:$1500,'Inventory Summary'!B$1&" "&'Inventory Summary'!$A13) -> 1 | D13: =COUNTIF('MekHQ Inventory Export'!$1:$1499,"Mech Right Torso "&$A13) -> 0 | E13: =COUNTIF('Parts Required'!$1:$1500,'Inventory Summary'!D$1&" "&'Inventory Summary'!$A13) -> 1 | F13: =COUNTIF('MekHQ Inventory Export'!$1:$1499,"Mech Left Torso"&$A13) -> 0 | G13: =COUNTIF('Parts Required'!$1:$1500,'Inventory Summary'!F$1&" "&'Inventory Summary'!$A13) -> 1 | H13: =COUNTIF('MekHQ Inventory Export'!$1:$1499,"Mech Right Arm "&$A13) -> 0 | I13: =COUNTIF('Parts Required'!$1:$1500,'Inventory Summary'!H$1&" "&'Inventory Summary'!$A13) -> 1 | J13: =COUNTIF('MekHQ Inventory Export'!$1:$1499,"Mech Left Arm "&$A13) -> 0 | K13: =COUNTIF('Parts Required'!$1:$1500,'Inventory Summary'!J$1&" "&'Inventory Summary'!$A13) -> 1 | L13: =COUNTIF('MekHQ Inventory Export'!$1:$1499,"Gyro "&$A13) -> 0 | M13: =COUNTIF('Parts Required'!$1:$1500,'Inventory Summary'!L$1&" "&'Inventory Summary'!$A13) -> 1 | N13: =COUNTIF('MekHQ Inventory Export'!$1:$1499,"Mech Sensors "&$A13) -> 1 | O13: =COUNTIF('Parts Required'!$1:$1500,'Inventory Summary'!N$1&" "&'Inventory Summary'!$A13) -> 0 | P13: =COUNTIF('MekHQ Inventory Export'!$1:$1499,"Mech Life Support System "&$A13) -> 0 | Q13: =COUNTIF('Parts Required'!$1:$1500,'Inventory Summary'!P$1&" "&'Inventory Summary'!$A13) -> 1 | R13: =COUNTIF('MekHQ Inventory Export'!$1:$1499,"Upper Arm Actuator "&$A13) -> 1 | S13: =COUNTIF('Parts Required'!$1:$1500,'Inventory Summary'!R$1&" "&'Inventory Summary'!$A13) -> 1 | T13: =COUNTIF('MekHQ Inventory Export'!$1:$1499,"Lower Arm Actuator "&$A13) -> 1 | U13: =COUNTIF('Parts Required'!$1:$1500,'Inventory Summary'!T$1&" "&'Inventory Summary'!$A13) -> 1 | V13: =COUNTIF('MekHQ Inventory Export'!$1:$1499,"Hamd Actuator "&$A13) -> 0 | W13: =COUNTIF('Parts Required'!$1:$1500,'Inventory Summary'!V$1&" "&'Inventory Summary'!$A13) -> 1 | X13: =COUNTIF('MekHQ Inventory Export'!$1:$1499,"Upper Leg Actuator "&$A13) -> 2 | Y13: =COUNTIF('Parts Required'!$1:$1500,'Inventory Summary'!X$1&" "&'Inventory Summary'!$A13) -> 1 | Z13: =COUNTIF('MekHQ Inventory Export'!$1:$1499,"Lower Leg Actuator"&$A13) -> 0 | AA13: =COUNTIF('Parts Required'!$1:$1500,'Inventory Summary'!Z$1&" "&'Inventory Summary'!$A13) -> 1 | AB13: =COUNTIF('MekHQ Inventory Export'!$1:$1499,"Foot Actuator "&$A13) -> 1 | AC13: =COUNTIF('Parts Required'!$1:$1500,'Inventory Summary'!AB$1&" "&'Inventory Summary'!$A13) -> 1
... A18: 100 tons | B18: =COUNTIF('MekHQ Inventory Export'!$1:$1499,"Mech Head "&$A18) -> 0 | C18: =COUNTIF('Parts Required'!$1:$1500,'Inventory Summary'!B$1&" "&'Inventory Summary'!$A18) -> 0 | D18: =COUNTIF('MekHQ Inventory Export'!$1:$1499,"Mech Right Torso "&$A18) -> 0 | E18: =COUNTIF('Parts Required'!$1:$1500,'Inventory Summary'!D$1&" "&'Inventory Summary'!$A18) -> 0 | F18: =COUNTIF('MekHQ Inventory Export'!$1:$1499,"Mech Left Torso"&$A18) -> 0 | G18: =COUNTIF('Parts Required'!$1:$1500,'Inventory Summary'!F$1&" "&'Inventory Summary'!$A18) -> 0 | H18: =COUNTIF('MekHQ Inventory Export'!$1:$1499,"Mech Right Arm "&$A18) -> 0 | I18: =COUNTIF('Parts Required'!$1:$1500,'Inventory Summary'!H$1&" "&'Inventory Summary'!$A18) -> 0 | J18: =COUNTIF('MekHQ Inventory Export'!$1:$1499,"Mech Left Arm "&$A18) -> 0 | K18: =COUNTIF('Parts Required'!$1:$1500,'Inventory Summary'!J$1&" "&'Inventory Summary'!$A18) -> 0 | L18: =COUNTIF('MekHQ Inventory Export'!$1:$1499,"Gyro "&$A18) -> 0 | M18: =COUNTIF('Parts Required'!$1:$1500,'Inventory Summary'!L$1&" "&'Inventory Summary'!$A18) -> 0 | N18: =COUNTIF('MekHQ Inventory Export'!$1:$1499,"Mech Sensors "&$A18) -> 0 | O18: =COUNTIF('Parts Required'!$1:$1500,'Inventory Summary'!N$1&" "&'Inventory Summary'!$A18) -> 0 | P18: =COUNTIF('MekHQ Inventory Export'!$1:$1499,"Mech Life Support System "&$A18) -> 0 | Q18: =COUNTIF('Parts Required'!$1:$1500,'Inventory Summary'!P$1&" "&'Inventory Summary'!$A18) -> 0 | R18: =COUNTIF('MekHQ Inventory Export'!$1:$1499,"Upper Arm Actuator "&$A18) -> 0 | S18: =COUNTIF('Parts Required'!$1:$1500,'Inventory Summary'!R$1&" "&'Inventory Summary'!$A18) -> 0 | T18: =COUNTIF('MekHQ Inventory Export'!$1:$1499,"Lower Arm Actuator "&$A18) -> 0 | U18: =COUNTIF('Parts Required'!$1:$1500,'Inventory Summary'!T$1&" "&'Inventory Summary'!$A18) -> 0 | V18: =COUNTIF('MekHQ Inventory Export'!$1:$1499,"Hamd Actuator "&$A18) -> 0 | W18: =COUNTIF('Parts Required'!$1:$1500,'Inventory Summary'!V$1&" "&'Inventory Summary'!$A18) -> 0 | X18: =COUNTIF('MekHQ Inventory Export'!$1:$1499,"Upper Leg Actuator "&$A18) -> 0 | Y18: =COUNTIF('Parts Required'!$1:$1500,'Inventory Summary'!X$1&" "&'Inventory Summary'!$A18) -> 0 | Z18: =COUNTIF('MekHQ Inventory Export'!$1:$1499,"Lower Leg Actuator"&$A18) -> 0 | AA18: =COUNTIF('Parts Required'!$1:$1500,'Inventory Summary'!Z$1&" "&'Inventory Summary'!$A18) -> 0 | AB18: =COUNTIF('MekHQ Inventory Export'!$1:$1499,"Foot Actuator "&$A18) -> 0 | AC18: =COUNTIF('Parts Required'!$1:$1500,'Inventory Summary'!AB$1&" "&'Inventory Summary'!$A18) -> 0
A20: Weapon | B20: # | C20: In Use
A21: Small Laser | B21: =COUNTIF('MekHQ Inventory Export'!$1:$1499,$A21) -> 1 | C21: =COUNTIF('Equipment Required'!$1:$1500,'Inventory Summary'!A21) -> 1
A22: Medium Laser | B22: =COUNTIF('MekHQ Inventory Export'!$1:$1499,$A22) -> 5 | C22: =COUNTIF('Equipment Required'!$1:$1500,'Inventory Summary'!A22) -> 8
A23: Large Laser | B23: =COUNTIF('MekHQ Inventory Export'!$1:$1499,$A23) -> 2 | C23: =COUNTIF('Equipment Required'!$1:$1500,'Inventory Summary'!A23) -> 0
A24: PPC | B24: =COUNTIF('MekHQ Inventory Export'!$1:$1499,$A24) -> 3 | C24: =COUNTIF('Equipment Required'!$1:$1500,'Inventory Summary'!A24) -> 0
A25: AC/2 | B25: =COUNTIF('MekHQ Inventory Export'!$1:$1499,$A25) -> 0 | C25: =COUNTIF('Equipment Required'!$1:$1500,'Inventory Summary'!A25) -> 0
A26: AC.5 | B26: =COUNTIF('MekHQ Inventory Export'!$1:$1499,$A26) -> 0 | C26: =COUNTIF('Equipment Required'!$1:$1500,'Inventory Summary'!A26) -> 0
A27: AC/10 | B27: =COUNTIF('MekHQ Inventory Export'!$1:$1499,$A27) -> 1 | C27: =COUNTIF('Equipment Required'!$1:$1500,'Inventory Summary'!A27) -> 0
A28: AC/20 | B28: =COUNTIF('MekHQ Inventory Export'!$1:$1499,$A28) -> 0 | C28: =COUNTIF('Equipment Required'!$1:$1500,'Inventory Summary'!A28) -> 0
A29: Machiune Gun | B29: =COUNTIF('MekHQ Inventory Export'!$1:$1499,$A29) -> 0 | C29: =COUNTIF('Equipment Required'!$1:$1500,'Inventory Summary'!A29) -> 0
A30: SRM 2 | B30: =COUNTIF('MekHQ Inventory Export'!$1:$1499,$A30) -> 3 | C30: =COUNTIF('Equipment Required'!$1:$1500,'Inventory Summary'!A30) -> 0
A31: SRM 4 | B31: =COUNTIF('MekHQ Inventory Export'!$1:$1499,$A31) -> 3 | C31: =COUNTIF('Equipment Required'!$1:$1500,'Inventory Summary'!A31) -> 0
A32: SRM 6 | B32: =COUNTIF('MekHQ Inventory Export'!$1:$1499,$A32) -> 3 | C32: =COUNTIF('Equipment Required'!$1:$1500,'Inventory Summary'!A32) -> 0
... A36: LRM 20 | B36: =COUNTIF('MekHQ Inventory Export'!$1:$1499,$A36) -> 1 | C36: =COUNTIF('Equipment Required'!$1:$1500,'Inventory Summary'!A36) -> 0
A37: Heat Sink | B37: =COUNTIF('MekHQ Inventory Export'!$1:$1499,$A37) -> 3 | C37: =SUM('Equipment Required'!C:C) -> 12
A39: Engine | B39: #
A40: 100 Fusion Engine | B40: =COUNTIF('MekHQ Inventory Export'!$1:$1499,$A40) -> 0 | C40: =COUNTIF('Equipment Required'!$1:$1500,'Inventory Summary'!A40) -> 0
A41: 105 Fusion Engine | B41: =COUNTIF('MekHQ Inventory Export'!$1:$1499,$A41) -> 0 | C41: =COUNTIF('Equipment Required'!$1:$1500,'Inventory Summary'!A41) -> 0
A42: 110 Fusion Engine | B42: =COUNTIF('MekHQ Inventory Export'!$1:$1499,$A42) -> 0 | C42: =COUNTIF('Equipment Required'!$1:$1500,'Inventory Summary'!A42) -> 0
A43: 115 Fusion Engine | B43: =COUNTIF('MekHQ Inventory Export'!$1:$1499,$A43) -> 0 | C43: =COUNTIF('Equipment Required'!$1:$1500,'Inventory Summary'!A43) -> 0
A44: 120 Fusion Engine | B44: =COUNTIF('MekHQ Inventory Export'!$1:$1499,$A44) -> 0 | C44: =COUNTIF('Equipment Required'!$1:$1500,'Inventory Summary'!A44) -> 0
A45: 125 Fusion Engine | B45: =COUNTIF('MekHQ Inventory Export'!$1:$1499,$A45) -> 0 | C45: =COUNTIF('Equipment Required'!$1:$1500,'Inventory Summary'!A45) -> 0
A46: 130 Fusion Engine | B46: =COUNTIF('MekHQ Inventory Export'!$1:$1499,$A46) -> 0 | C46: =COUNTIF('Equipment Required'!$1:$1500,'Inventory Summary'!A46) -> 0
A47: 135 Fusion Engine | B47: =COUNTIF('MekHQ Inventory Export'!$1:$1499,$A47) -> 0 | C47: =COUNTIF('Equipment Required'!$1:$1500,'Inventory Summary'!A47) -> 0
A48: 140 Fusion Engine | B48: =COUNTIF('MekHQ Inventory Export'!$1:$1499,$A48) -> 0 | C48: =COUNTIF('Equipment Required'!$1:$1500,'Inventory Summary'!A48) -> 0
A49: 145 Fusion Engine | B49: =COUNTIF('MekHQ Inventory Export'!$1:$1499,$A49) -> 0 | C49: =COUNTIF('Equipment Required'!$1:$1500,'Inventory Summary'!A49) -> 0
...

Sheet Parts Required
A1: Unit | B1: Type | C1: Tonnage | D1: Mech Head | E1: Mech Right Torso | F1: Mech Left Torso | G1: Mech Right Arm | H1: Mech Left Arm | I1: Mech Gyro | J1: Mech Life Support System | K1: Upper Arm Actuator | L1: Lower Arm Actuator | M1: Hand Actuator | N1: Upper Leg Actator | O1: Lower Leg Actutor | P1: Foot Actuator
A2: =IF(TOE!A2="","",TOE!A2) -> Lightning LTN-G15 | B2: =IF(TOE!B2="","",TOE!B2) -> Aerospace Fighter | C2: =IF(TOE!E2="","",TOE!E2) -> 50 | D2: =IF(TOE!$B2="Mek",IF($A2="","",D$1&" "&$C2&" tons"),"") | E2: =IF(TOE!$B2="Mek",IF($A2="","",E$1&" "&$C2&" tons"),"") | F2: =IF(TOE!$B2="Mek",IF($A2="","",F$1&" "&$C2&" tons"),"") | G2: =IF(TOE!$B2="Mek",IF($A2="","",G$1&" "&$C2&" tons"),"") | H2: =IF(TOE!$B2="Mek",IF($A2="","",H$1&" "&$C2&" tons"),"") | I2: =IF(TOE!$B2="Mek",IF($A2="","",I$1&" "&$C2&" tons"),"") | J2: =IF(TOE!$B2="Mek",IF($A2="","",J$1&" "&$C2&" tons"),"") | K2: =IF(TOE!$B2="Mek",IF($A2="","",K$1&" "&$C2&" tons"),"") | ... P2: =IF(TOE!$B2="Mek",IF($A2="","",P$1&" "&$C2&" tons"),"")
A3: =IF(TOE!A3="","",TOE!A3) -> Stingray F-90 | B3: =IF(TOE!B3="","",TOE!B3) -> Aerospace Fighter | C3: =IF(TOE!E3="","",TOE!E3) -> 60 | D3: =IF(TOE!$B3="Mek",IF($A3="","",D$1&" "&$C3&" tons"),"") | E3: =IF(TOE!$B3="Mek",IF($A3="","",E$1&" "&$C3&" tons"),"") | F3: =IF(TOE!$B3="Mek",IF($A3="","",F$1&" "&$C3&" tons"),"") | G3: =IF(TOE!$B3="Mek",IF($A3="","",G$1&" "&$C3&" tons"),"") | H3: =IF(TOE!$B3="Mek",IF($A3="","",H$1&" "&$C3&" tons"),"") | I3: =IF(TOE!$B3="Mek",IF($A3="","",I$1&" "&$C3&" tons"),"") | J3: =IF(TOE!$B3="Mek",IF($A3="","",J$1&" "&$C3&" tons"),"") | K3: =IF(TOE!$B3="Mek",IF($A3="","",K$1&" "&$C3&" tons"),"") | ... P3: =IF(TOE!$B3="Mek",IF($A3="","",P$1&" "&$C3&" tons"),"")
A4: =IF(TOE!A4="","",TOE!A4) -> Boomerang Spotter Plane | B4: =IF(TOE!B4="","",TOE!B4) -> Conventional Fighter | C4: =IF(TOE!E4="","",TOE!E4) -> 4.999 | D4: =IF(TOE!$B4="Mek",IF($A4="","",D$1&" "&$C4&" tons"),"") | E4: =IF(TOE!$B4="Mek",IF($A4="","",E$1&" "&$C4&" tons"),"") | F4: =IF(TOE!$B4="Mek",IF($A4="","",F$1&" "&$C4&" tons"),"") | G4: =IF(TOE!$B4="Mek",IF($A4="","",G$1&" "&$C4&" tons"),"") | H4: =IF(TOE!$B4="Mek",IF($A4="","",H$1&" "&$C4&" tons"),"") | I4: =IF(TOE!$B4="Mek",IF($A4="","",I$1&" "&$C4&" tons"),"") | J4: =IF(TOE!$B4="Mek",IF($A4="","",J$1&" "&$C4&" tons"),"") | K4: =IF(TOE!$B4="Mek",IF($A4="","",K$1&" "&$C4&" tons"),"") | ... P4: =IF(TOE!$B4="Mek",IF($A4="","",P$1&" "&$C4&" tons"),"")
A5: =IF(TOE!A5="","",TOE!A5) -> Leopard (Black Swan Mk III) - The Black Swan | B5: =IF(TOE!B5="","",TOE!B5) -> Dropship | C5: =IF(TOE!E5="","",TOE!E5) -> 1900 | D5: =IF(TOE!$B5="Mek",IF($A5="","",D$1&" "&$C5&" tons"),"") | E5: =IF(TOE!$B5="Mek",IF($A5="","",E$1&" "&$C5&" tons"),"") | F5: =IF(TOE!$B5="Mek",IF($A5="","",F$1&" "&$C5&" tons"),"") | G5: =IF(TOE!$B5="Mek",IF($A5="","",G$1&" "&$C5&" tons"),"") | H5: =IF(TOE!$B5="Mek",IF($A5="","",H$1&" "&$C5&" tons"),"") | I5: =IF(TOE!$B5="Mek",IF($A5="","",I$1&" "&$C5&" tons"),"") | J5: =IF(TOE!$B5="Mek",IF($A5="","",J$1&" "&$C5&" tons"),"") | K5: =IF(TOE!$B5="Mek",IF($A5="","",K$1&" "&$C5&" tons"),"") | ... P5: =IF(TOE!$B5="Mek",IF($A5="","",P$1&" "&$C5&" tons"),"")
A6: =IF(TOE!A6="","",TOE!A6) -> Union (2708) | B6: =IF(TOE!B6="","",TOE!B6) -> Dropship | C6: =IF(TOE!E6="","",TOE!E6) -> 3600 | D6: =IF(TOE!$B6="Mek",IF($A6="","",D$1&" "&$C6&" tons"),"") | E6: =IF(TOE!$B6="Mek",IF($A6="","",E$1&" "&$C6&" tons"),"") | F6: =IF(TOE!$B6="Mek",IF($A6="","",F$1&" "&$C6&" tons"),"") | G6: =IF(TOE!$B6="Mek",IF($A6="","",G$1&" "&$C6&" tons"),"") | H6: =IF(TOE!$B6="Mek",IF($A6="","",H$1&" "&$C6&" tons"),"") | I6: =IF(TOE!$B6="Mek",IF($A6="","",I$1&" "&$C6&" tons"),"") | J6: =IF(TOE!$B6="Mek",IF($A6="","",J$1&" "&$C6&" tons"),"") | K6: =IF(TOE!$B6="Mek",IF($A6="","",K$1&" "&$C6&" tons"),"") | ... P6: =IF(TOE!$B6="Mek",IF($A6="","",P$1&" "&$C6&" tons"),"")
A7: =IF(TOE!A7="","",TOE!A7) -> Gazelle (Heavy Vehicle) Mk II | B7: =IF(TOE!B7="","",TOE!B7) -> Dropship | C7: =IF(TOE!E7="","",TOE!E7) -> 2900 | D7: =IF(TOE!$B7="Mek",IF($A7="","",D$1&" "&$C7&" tons"),"") | E7: =IF(TOE!$B7="Mek",IF($A7="","",E$1&" "&$C7&" tons"),"") | F7: =IF(TOE!$B7="Mek",IF($A7="","",F$1&" "&$C7&" tons"),"") | G7: =IF(TOE!$B7="Mek",IF($A7="","",G$1&" "&$C7&" tons"),"") | H7: =IF(TOE!$B7="Mek",IF($A7="","",H$1&" "&$C7&" tons"),"") | I7: =IF(TOE!$B7="Mek",IF($A7="","",I$1&" "&$C7&" tons"),"") | J7: =IF(TOE!$B7="Mek",IF($A7="","",J$1&" "&$C7&" tons"),"") | K7: =IF(TOE!$B7="Mek",IF($A7="","",K$1&" "&$C7&" tons"),"") | ... P7: =IF(TOE!$B7="Mek",IF($A7="","",P$1&" "&$C7&" tons"),"")
A8: =IF(TOE!A8="","",TOE!A8) -> Jump Platoon (Rifle) | B8: =IF(TOE!B8="","",TOE!B8) -> Infantry | C8: =IF(TOE!E8="","",TOE!E8) -> 4 | D8: =IF(TOE!$B8="Mek",IF($A8="","",D$1&" "&$C8&" tons"),"") | E8: =IF(TOE!$B8="Mek",IF($A8="","",E$1&" "&$C8&" tons"),"") | F8: =IF(TOE!$B8="Mek",IF($A8="","",F$1&" "&$C8&" tons"),"") | G8: =IF(TOE!$B8="Mek",IF($A8="","",G$1&" "&$C8&" tons"),"") | H8: =IF(TOE!$B8="Mek",IF($A8="","",H$1&" "&$C8&" tons"),"") | I8: =IF(TOE!$B8="Mek",IF($A8="","",I$1&" "&$C8&" tons"),"") | J8: =IF(TOE!$B8="Mek",IF($A8="","",J$1&" "&$C8&" tons"),"") | K8: =IF(TOE!$B8="Mek",IF($A8="","",K$1&" "&$C8&" tons"),"") | ... P8: =IF(TOE!$B8="Mek",IF($A8="","",P$1&" "&$C8&" tons"),"")
A9: =IF(TOE!A9="","",TOE!A9) -> Jump Platoon (SRM) | B9: =IF(TOE!B9="","",TOE!B9) -> Infantry | C9: =IF(TOE!E9="","",TOE!E9) -> 3.5 | D9: =IF(TOE!$B9="Mek",IF($A9="","",D$1&" "&$C9&" tons"),"") | E9: =IF(TOE!$B9="Mek",IF($A9="","",E$1&" "&$C9&" tons"),"") | F9: =IF(TOE!$B9="Mek",IF($A9="","",F$1&" "&$C9&" tons"),"") | G9: =IF(TOE!$B9="Mek",IF($A9="","",G$1&" "&$C9&" tons"),"") | H9: =IF(TOE!$B9="Mek",IF($A9="","",H$1&" "&$C9&" tons"),"") | I9: =IF(TOE!$B9="Mek",IF($A9="","",I$1&" "&$C9&" tons"),"") | J9: =IF(TOE!$B9="Mek",IF($A9="","",J$1&" "&$C9&" tons"),"") | K9: =IF(TOE!$B9="Mek",IF($A9="","",K$1&" "&$C9&" tons"),"") | ... P9: =IF(TOE!$B9="Mek",IF($A9="","",P$1&" "&$C9&" tons"),"")
A10: =IF(TOE!A10="","",TOE!A10) -> Jump Platoon (Flamer) | B10: =IF(TOE!B10="","",TOE!B10) -> Infantry | C10: =IF(TOE!E10="","",TOE!E10) -> 4 | D10: =IF(TOE!$B10="Mek",IF($A10="","",D$1&" "&$C10&" tons"),"") | E10: =IF(TOE!$B10="Mek",IF($A10="","",E$1&" "&$C10&" tons"),"") | F10: =IF(TOE!$B10="Mek",IF($A10="","",F$1&" "&$C10&" tons"),"") | G10: =IF(TOE!$B10="Mek",IF($A10="","",G$1&" "&$C10&" tons"),"") | H10: =IF(TOE!$B10="Mek",IF($A10="","",H$1&" "&$C10&" tons"),"") | I10: =IF(TOE!$B10="Mek",IF($A10="","",I$1&" "&$C10&" tons"),"") | J10: =IF(TOE!$B10="Mek",IF($A10="","",J$1&" "&$C10&" tons"),"") | K10: =IF(TOE!$B10="Mek",IF($A10="","",K$1&" "&$C10&" tons"),"") | ... P10: =IF(TOE!$B10="Mek",IF($A10="","",P$1&" "&$C10&" tons"),"")
A11: =IF(TOE!A11="","",TOE!A11) -> Jump Platoon (Rifle) #2 | B11: =IF(TOE!B11="","",TOE!B11) -> Infantry | C11: =IF(TOE!E11="","",TOE!E11) -> 4 | D11: =IF(TOE!$B11="Mek",IF($A11="","",D$1&" "&$C11&" tons"),"") | E11: =IF(TOE!$B11="Mek",IF($A11="","",E$1&" "&$C11&" tons"),"") | F11: =IF(TOE!$B11="Mek",IF($A11="","",F$1&" "&$C11&" tons"),"") | G11: =IF(TOE!$B11="Mek",IF($A11="","",G$1&" "&$C11&" tons"),"") | H11: =IF(TOE!$B11="Mek",IF($A11="","",H$1&" "&$C11&" tons"),"") | I11: =IF(TOE!$B11="Mek",IF($A11="","",I$1&" "&$C11&" tons"),"") | J11: =IF(TOE!$B11="Mek",IF($A11="","",J$1&" "&$C11&" tons"),"") | K11: =IF(TOE!$B11="Mek",IF($A11="","",K$1&" "&$C11&" tons"),"") | ... P11: =IF(TOE!$B11="Mek",IF($A11="","",P$1&" "&$C11&" tons"),"")
A12: =IF(TOE!A12="","",TOE!A12) -> Foot Platoon (Laser Marine) | B12: =IF(TOE!B12="","",TOE!B12) -> Infantry | C12: =IF(TOE!E12="","",TOE!E12) -> 2.5 | D12: =IF(TOE!$B12="Mek",IF($A12="","",D$1&" "&$C12&" tons"),"") | E12: =IF(TOE!$B12="Mek",IF($A12="","",E$1&" "&$C12&" tons"),"") | F12: =IF(TOE!$B12="Mek",IF($A12="","",F$1&" "&$C12&" tons"),"") | G12: =IF(TOE!$B12="Mek",IF($A12="","",G$1&" "&$C12&" tons"),"") | H12: =IF(TOE!$B12="Mek",IF($A12="","",H$1&" "&$C12&" tons"),"") | I12: =IF(TOE!$B12="Mek",IF($A12="","",I$1&" "&$C12&" tons"),"") | J12: =IF(TOE!$B12="Mek",IF($A12="","",J$1&" "&$C12&" tons"),"") | K12: =IF(TOE!$B12="Mek",IF($A12="","",K$1&" "&$C12&" tons"),"") | ... P12: =IF(TOE!$B12="Mek",IF($A12="","",P$1&" "&$C12&" tons"),"")
A13: =IF(TOE!A13="","",TOE!A13) -> Foot Platoon (Laser Marine) #2 | B13: =IF(TOE!B13="","",TOE!B13) -> Infantry | C13: =IF(TOE!E13="","",TOE!E13) -> 2.5 | D13: =IF(TOE!$B13="Mek",IF($A13="","",D$1&" "&$C13&" tons"),"") | E13: =IF(TOE!$B13="Mek",IF($A13="","",E$1&" "&$C13&" tons"),"") | F13: =IF(TOE!$B13="Mek",IF($A13="","",F$1&" "&$C13&" tons"),"") | G13: =IF(TOE!$B13="Mek",IF($A13="","",G$1&" "&$C13&" tons"),"") | H13: =IF(TOE!$B13="Mek",IF($A13="","",H$1&" "&$C13&" tons"),"") | I13: =IF(TOE!$B13="Mek",IF($A13="","",I$1&" "&$C13&" tons"),"") | J13: =IF(TOE!$B13="Mek",IF($A13="","",J$1&" "&$C13&" tons"),"") | K13: =IF(TOE!$B13="Mek",IF($A13="","",K$1&" "&$C13&" tons"),"") | ... P13: =IF(TOE!$B13="Mek",IF($A13="","",P$1&" "&$C13&" tons"),"")
... A55: =IF(TOE!A55="","",TOE!A55) -> Warrior Attack Helicopter H-7 | B55: =IF(TOE!B55="","",TOE!B55) -> VTOL | C55: =IF(TOE!E55="","",TOE!E55) -> 21 | D55: =IF(TOE!$B55="Mek",IF($A55="","",D$1&" "&$C55&" tons"),"") | E55: =IF(TOE!$B55="Mek",IF($A55="","",E$1&" "&$C55&" tons"),"") | F55: =IF(TOE!$B55="Mek",IF($A55="","",F$1&" "&$C55&" tons"),"") | G55: =IF(TOE!$B55="Mek",IF($A55="","",G$1&" "&$C55&" tons"),"") | H55: =IF(TOE!$B55="Mek",IF($A55="","",H$1&" "&$C55&" tons"),"") | I55: =IF(TOE!$B55="Mek",IF($A55="","",I$1&" "&$C55&" tons"),"") | J55: =IF(TOE!$B55="Mek",IF($A55="","",J$1&" "&$C55&" tons"),"") | K55: =IF(TOE!$B55="Mek",IF($A55="","",K$1&" "&$C55&" tons"),"") | ... P55: =IF(TOE!$B55="Mek",IF($A55="","",P$1&" "&$C55&" tons"),"")
C56: =IF(TOE!E56="","",TOE!E56) | D56: =IF(TOE!$B56="Mek",IF($A56="","",D$1&" "&$C56&" tons"),"") | E56: =IF(TOE!$B56="Mek",IF($A56="","",E$1&" "&$C56&" tons"),"") | F56: =IF(TOE!$B56="Mek",IF($A56="","",F$1&" "&$C56&" tons"),"") | G56: =IF(TOE!$B56="Mek",IF($A56="","",G$1&" "&$C56&" tons"),"") | H56: =IF(TOE!$B56="Mek",IF($A56="","",H$1&" "&$C56&" tons"),"") | I56: =IF(TOE!$B56="Mek",IF($A56="","",I$1&" "&$C56&" tons"),"") | J56: =IF(TOE!$B56="Mek",IF($A56="","",J$1&" "&$C56&" tons"),"") | K56: =IF(TOE!$B56="Mek",IF($A56="","",K$1&" "&$C56&" tons"),"") | ... P56: =IF(TOE!$B56="Mek",IF($A56="","",P$1&" "&$C56&" tons"),"")
C57: =IF(TOE!E57="","",TOE!E57) | D57: =IF(TOE!$B57="Mek",IF($A57="","",D$1&" "&$C57&" tons"),"") | E57: =IF(TOE!$B57="Mek",IF($A57="","",E$1&" "&$C57&" tons"),"") | F57: =IF(TOE!$B57="Mek",IF($A57="","",F$1&" "&$C57&" tons"),"") | G57: =IF(TOE!$B57="Mek",IF($A57="","",G$1&" "&$C57&" tons"),"") | H57: =IF(TOE!$B57="Mek",IF($A57="","",H$1&" "&$C57&" tons"),"") | I57: =IF(TOE!$B57="Mek",IF($A57="","",I$1&" "&$C57&" tons"),"") | J57: =IF(TOE!$B57="Mek",IF($A57="","",J$1&" "&$C57&" tons"),"") | K57: =IF(TOE!$B57="Mek",IF($A57="","",K$1&" "&$C57&" tons"),"") | ... P57: =IF(TOE!$B57="Mek",IF($A57="","",P$1&" "&$C57&" tons"),"")

Sheet Equipment Required
A1: Unit | B1: Engine | C1: Heat Sinks | D1: Weapons
A2: =IF(TOE!A2="","",TOE!A2) -> Lightning LTN-G15
A3: =IF(TOE!A3="","",TOE!A3) -> Stingray F-90
A4: =IF(TOE!A4="","",TOE!A4) -> Boomerang Spotter Plane
A5: =IF(TOE!A5="","",TOE!A5) -> Leopard (Black Swan Mk III) - The Black Swan
A6: =IF(TOE!A6="","",TOE!A6) -> Union (2708)
A7: =IF(TOE!A7="","",TOE!A7) -> Gazelle (Heavy Vehicle) Mk II
A8: =IF(TOE!A8="","",TOE!A8) -> Jump Platoon (Rifle)
A9: =IF(TOE!A9="","",TOE!A9) -> Jump Platoon (SRM)
A10: =IF(TOE!A10="","",TOE!A10) -> Jump Platoon (Flamer)
A11: =IF(TOE!A11="","",TOE!A11) -> Jump Platoon (Rifle) #2
A12: =IF(TOE!A12="","",TOE!A12) -> Foot Platoon (Laser Marine)
A13: =IF(TOE!A13="","",TOE!A13) -> Foot Platoon (Laser Marine) #2
... A15: =IF(TOE!A15="","",TOE!A15) -> Javelin JVN-10F 'Fire Javelin'
A16: =IF(TOE!A16="","",TOE!A16) -> Hunchback HBK-4P | B16: 200 Fusion Engine | C16: 12 | D16: Medium Laser | E16: Medium Laser | F16: Medium Laser | G16: Medium Laser | H16: Medium Laser | I16: Medium Laser | J16: Medium Laser | K16: Medium Laser | L16: Small Laser
A17: =IF(TOE!A17="","",TOE!A17) -> Griffin GRF-1S
A18: =IF(TOE!A18="","",TOE!A18) -> Black Knight BL-7-KNT-L
A19: =IF(TOE!A19="","",TOE!A19) -> Grasshopper GHR-5H
A20: =IF(TOE!A20="","",TOE!A20) -> Stalker STK-4N
A21: =IF(TOE!A21="","",TOE!A21) -> Hunchback HBK-4P #2
A22: =IF(TOE!A22="","",TOE!A22) -> Thunderbolt TDR-5SS
A23: =IF(TOE!A23="","",TOE!A23) -> Rifleman RFL-3N
A24: =IF(TOE!A24="","",TOE!A24) -> Thunderbolt TDR-5SS #2
A25: =IF(TOE!A25="","",TOE!A25) -> Cicada CDA-3C
A26: =IF(TOE!A26="","",TOE!A26) -> Trebuchet TBT-5S
A27: =IF(TOE!A27="","",TOE!A27) -> Stalker STK-3F
A28: =IF(TOE!A28="","",TOE!A28) -> Spider SDR-5V
... A50: =IF(TOE!A50="","",TOE!A50) -> Strike Falcon Attack VTOL

Sheet MekHQ Inventory Export
A1: /part/name | B1: /part/unitTonnage
A2: Upper Arm Actuator | B2: 30 | C2: =A2&" "&B2&" tons" -> Upper Arm Actuator 30 tons
A3: Lower Arm Actuator | B3: 30 | C3: =A3&" "&B3&" tons" -> Lower Arm Actuator 30 tons
A4: Hand Actuator | B4: 30 | C4: =A4&" "&B4&" tons" -> Hand Actuator 30 tons
A5: Upper Leg Actuator | B5: 30 | C5: =A5&" "&B5&" tons" -> Upper Leg Actuator 30 tons
A6: Foot Actuator | B6: 30 | C6: =A6&" "&B6&" tons" -> Foot Actuator 30 tons
A7: Mech Life Support System | B7: 0 | C7: =A7&" "&B7&" tons" -> Mech Life Support System 0 tons
A8: Mech Sensors | B8: 30 | C8: =A8&" "&B8&" tons" -> Mech Sensors 30 tons
A9: Mech Sensors | B9: 50 | C9: =A9&" "&B9&" tons" -> Mech Sensors 50 tons
A10: Mech Sensors | B10: 55 | C10: =A10&" "&B10&" tons" -> Mech Sensors 55 tons
A11: Mech Sensors | B11: 65 | C11: =A11&" "&B11&" tons" -> Mech Sensors 65 tons
A12: Mech Sensors | B12: 70 | C12: =A12&" "&B12&" tons" -> Mech Sensors 70 tons
A13: Mech Sensors | B13: 75 | C13: =A13&" "&B13&" tons" -> Mech Sensors 75 tons
... A207: Armor (Standard) | B207: 0 | C207: =A207&" "&B207&" tons" -> Armor (Standard) 0 tons
